Workbook

Sheet BOM
A1: terraPen A2 – Bill of Materials (v2.4)
A2: Public bill of materials for one terraPen A2. Prices are kept in a separate internal workbook.
A3: Status: | B3: OK – matches old master | C3: CHANGED – qty differs from old master | E3: NEW – missing from old master | F3: CHECK – needs your decision
A5: Ref | B5: Part | C5: Spec / size | D5: Qty | E5: Used in | F5: Supplier | G5: Primary link | H5: eBay UK | I5: Amazon UK | J5: AliExpress
A6: 1 FRAME & STRUCTURE
A7: 1.01 | B7: 2020 T-slot extrusion | C7: 760 mm, cut, M5 tapped both ends | D7: 4 | E7: Frame – width | F7: KJN Aluminium Profile (cut to size) | G7: Open page | H7: eBay | I7: Amazon | J7: AliExpress
A8: 1.02 | B8: 2020 T-slot extrusion | C8: 560 mm, cut, M5 tapped both ends | D8: 4 | E8: Frame – length | F8: KJN Aluminium Profile (cut to size) | G8: Open page | H8: eBay | I8: Amazon | J8: AliExpress
A9: 1.03 | B9: 2020 T-slot extrusion | C9: 710 mm, cut (X rail) | D9: 1 | E9: Frame – X rail | F9: KJN Aluminium Profile (cut to size) | G9: Open page | H9: eBay | I9: Amazon | J9: AliExpress
A10: 1.04 | B10: 2020 T-slot extrusion | C10: 50 mm, cut (uprights / legs), M5 tapped both ends | D10: 4 | E10: Frame – height | F10: KJN Aluminium Profile (cut to size) | G10: Open page | H10: eBay | I10: Amazon | J10: AliExpress
A11: 1.05 | B11: 2020 corner cube connector | C11: 3-way, 20x20x20, black, 6 mm T-slot; sold as 12 with screws | D11: 8 | E11: Frame – corners | F11: AliExpress (12 pcs) | G11: Open page | H11: eBay | I11: Amazon | J11: AliExpress
A12: 1.06 | B12: 2020 corner bracket | C12: 90 degree, 20 x 20 x 17 mm aluminium; sold as 10 (5 machines) | D12: 2 | E12: Frame | F12: AliExpress (10 pcs) | G12: Open page | H12: eBay | I12: Amazon | J12: AliExpress
A13: 1.07 | B13: Rubber feet | C13: 20 mm dia x 15 mm high, conical black rubber with steel washer; sold in lots of 4 (one machine) | D13: 4 | E13: Frame – base | F13: AliExpress (lot of 4) | G13: Open page | H13: eBay | I13: Amazon | J13: AliExpress
A14: 1.09 | B14: Metal baseboard with vinyl sticker | C14: Ferrous Dibond-style composite, cut to shape; profile 'tP_Bed_Profile_Revised.dxf', artwork 'Diabond vinyl revised .ai' (both in /metal bed) | D14: 1 | E14: Base | F14: Local sign shop | G14: DXF file | H14: – | I14: – | J14: –
A15: 1.10 | B15: IR Cover reduction profile (5), black (cosmetic slot cover) | C15: KJN37080, 2 m lengths, fits the 5 mm slot; cut list about 5.8 m (6 x 560, 2 x 760, 1 x 710, 4 x 50 mm) | D15: 3 | E15: Frame – top and side trim, front legs | F15: KJN Aluminium Profile | G15: Open page
A16: 1.11 | B16: Corner cube hole caps, plastic | C16: 11 mm plastic caps; sold as 100 pcs | D16: 12 | E16: Frame corners (cubes) | F16: eBay UK (100 pcs) | G16: Open page
A17: 1.12 | B17: Rubber bungs | C17: 11 mm rubber bungs; sold as 50 pcs | D17: 8 | E17: Both sides of the plotter | F17: eBay UK (50 pcs) | G17: Open page
A18: 1.13 | B18: Neodymium magnets | C18: Strong rare-earth magnets; sold as 50 | D18: 4 | E18: Metal bed (4 per machine); where exactly to confirm | F18: eBay UK (50 pcs) | G18: Open page
A19: 1.14 | B19: Neodymium magnets, black, second listing | C19: Sold as 4 | D19: 4 | E19: To confirm | F19: eBay UK (4 pcs) | G19: Open page
A20: 2 LINEAR MOTION
A21: 2.01 | B21: Linear rail + 1 block, MGN9H | C21: 540 mm (Y axis) | D21: 2 | E21: Y left / Y right | F21: Jugetek (custom cut) | G21: Open page | H21: eBay | I21: Amazon | J21: AliExpress
A22: 2.02 | B22: Linear rail + 1 block, MGN9H | C22: 710 mm (X axis) | D22: 1 | E22: X rail / carriage | F22: Jugetek (custom cut) | G22: Open page | H22: eBay | I22: Amazon | J22: AliExpress
A23: 2.03 | B23: Linear rail + 1 block, MGN7H | C23: 50 mm (Z / pen lift) | D23: 1 | E23: Tool head | F23: Jugetek (custom cut) | G23: Open page | H23: eBay | I23: Amazon | J23: AliExpress
A24: 3 DRIVE – BELTS, PULLEYS, MOTORS
A25: 3.01 | B25: GT2 timing belt, open | C25: 6 mm wide, open-ended, rubber/aramid; 4.2 m per machine (qty is in metres) | D25: 4.2 | E25: X and Y belts | F25: AliExpress (5 m length) | G25: Open page | H25: eBay | I25: Amazon | J25: AliExpress
A26: 3.02 | B26: GT2 pulley, toothed drive | C26: 20T, 5 mm bore, 6 mm belt; sold as 10 | D26: 2 | E26: X motor, Y motor | F26: AliExpress (10 pcs) | G26: Open page | H26: eBay | I26: Amazon | J26: AliExpress
A27: 3.03 | B27: GT2 idler, smooth | C27: 20T smooth (no teeth), 5 mm bore, 6 mm belt, with bearing; sold as 4 | D27: 4 | E27: X/Y idlers, Y left/right, motor mounts | F27: AliExpress (4 pcs) | G27: Open page | H27: eBay | I27: Amazon | J27: AliExpress
A28: 3.04 | B28: GT2 idler, toothed | C28: 20T, 5 mm bore, 6 mm belt, with bearing; sold as 10 | D28: 8 | E28: X/Y idlers, Y left/right, motor mounts | F28: AliExpress (10 pcs) | G28: Open page | H28: eBay | I28: Amazon | J28: AliExpress
A29: 3.05 | B29: NEMA 17 stepper motor, 17HS15-1504S-X1 | C29: 42x42x39 mm (page also says 40), 1.8 deg, 1.5 A, 45 N.cm, 2.3 ohm, 4.4 mH; 5 mm D-cut shaft; 1 m lead with pin connector | D29: 2 | E29: X motor, Y motor | F29: StepperOnline UK | G29: Open page | H29: eBay | I29: Amazon | J29: AliExpress
A30: 4 ELECTRONICS
A31: 4.01 | B31: Emerald Dingo ESP32 plotter controller (RevB) | C31: FluidNC, 2-axis, TMC2130 driver sockets, USB-C | D31: 1 | E31: Electronics enclosure | F31: terrapen.xyz | G31: Open page | H31: – | I31: – | J31: –
A32: 4.02 | B32: TMC2130 stepper driver | C32: 3: X, Y and Z (Z via the Z-axis add-on) | D32: 3 | E32: Controller | F32: AliExpress | G32: Open page | H32: – | I32: – | J32: –
A33: 4.03 | B33: Emerald Dingo Z-axis add-on | C33: Z motor add-on; the Z lead plugs into this | D33: 1 | E33: Controller | F33: terrapen.xyz | G33: Open page | H33: – | I33: – | J33: –
A34: 4.04 | B34: Micro SD card, 2 GB | C34: Cloudisk 2 GB microSD with adapter; sold as 5 | D34: 1 | E34: Controller | F34: Amazon UK (5 pack) | G34: Open page | H34: eBay | I34: Amazon | J34: AliExpress
A35: 4.05 | B35: Power supply, 12 V dc, 2.5 A (Ideal Power 15DYS830-120250W-K) | C35: 12 V 2.5 A, 2.1 x 5.5 mm centre-positive barrel plug, 1.5 m lead, interchangeable AU/EU/UK/US mains plugs | D35: 1 | E35: Power | F35: Farnell UK | G35: Open page | H35: eBay | I35: Amazon | J35: AliExpress
A36: 4.06 | B36: Motor cable, 4-way | C36: 4-core PVC cable, 26 AWG, flexible, unshielded, 920 mm, JST PH 2.0 | D36: 1 | E36: X motor | G36: – | H36: eBay | I36: Amazon | J36: AliExpress
A37: 4.07 | B37: Motor cable, 4-way | C37: 4-core PVC cable, 26 AWG, flexible, unshielded, 515 mm, JST PH 2.0 | D37: 1 | E37: Y motor | G37: – | H37: eBay | I37: Amazon | J37: AliExpress
A38: 4.08 | B38: Hook-up wire, Alpha Wire 3049 BK001 | C38: 26 AWG PVC black, 7 x 34 tinned stranded, 300 V (order code 01-5540). Sold on a 1000 ft (304.8 m) reel; only part of it is used per machine | D38: 15 | E38: Z motor lead (4 x 2100 mm) and X endstop lead (3 x 2100 mm) = 14.7 m, 15 m with trimming | F38: Rapid Electronics | G38: Open page | H38: – | I38: – | J38: –
A39: 4.09 | B39: Multicore cable, 4-core PVC | C39: 26 AWG, flexible PVC, unshielded: X lead 920 mm + Y lead 515 mm (1.435 m), plus spare | D39: 1.5 | E39: X and Y motors | F39: eBay UK (20 m reel) | G39: Open page | H39: eBay | I39: Amazon | J39: AliExpress
A40: 4.10 | B40: Multicore cable, 3-core PVC | C40: 3-core PVC, 26 AWG (confirm); Y endstop lead only, 920 mm, plus spare | D40: 1 | E40: Y endstop | F40: eBay UK (20 m reel) | G40: Open page | H40: eBay | I40: Amazon | J40: AliExpress
A41: 4.11 | B41: JST PH 2.0 connector kit | C41: 420 pcs: PH housings (2 to 6-way, male and female) and 270 crimp terminals; sold as one kit | D41: 1 | E41: All JST PH plugs: controller ends (3 x 4-way motor/Z, 2 x 3-way endstop) and motor ends (2 x 6-way) | F41: eBay UK (kit) | G41: Open page | H41: eBay | I41: Amazon | J41: AliExpress
...

Sheet Fixings by part
A1: Fixings by part – walk-through of the build, bottom frame upwards (work in progress)
A2: Dictated by Ed on 24 Oct 2026. Totals are reconciled against the BOM sheet afterwards.
A4: Assembly / part | B4: Fastener | C4: Qty | D4: Nut / insert | E4: Qty | F4: Supplied with part? | G4: BOM row | H4: Notes | I4: Screw key | J4: Nut key
A5: Bottom frame – rubber feet | B5: Button head screw, approx. M3 x 16 (length to confirm) | C5: 4 | D5: M3 spring-ball T-slot nut (KJN43719) | E5: 4 | F5: Yes, screws came with the feet | G5: 1.07, 7.10, 7.14 | H5: Per Ed. The BOM currently lists 4 x M3 x 12 button head for 'Frame – feet' (7.10): check whether that should be dropped or changed to 16 mm. The 4 nuts are part of the 16 M3 nuts. | I5: M3 x 16 button head (approx.) | J5: M3 T-nut
A6: Bottom frame – 4 extrusions + 4 corner cubes (square) | B6: Socket head (cap) screw M5 x 12 | C6: 8 | D6: None (bolts go into the tapped extrusion ends) | F6: No | G6: 1.01, 1.02, 1.05, 8.03 | H6: Per Ed: M5 x 12 is enough (16 was considered). 2 bolts per cube x 4 cubes = 8. The third hole of each cube is still to be covered (uprights?). BOM row 8.03 has 22 in total for the whole frame. | I6: M5 x 12 cap head
A7: Bottom frame – bed support extrusion (horizontal cross-member, keeps the frame square), 2 x L brackets | B7: Button head screw M5 x 8 | C7: 4 | D7: M5 spring-ball T-slot nut (KJN37001) | E7: 4 | F7: No | G7: 1.06, 8.05, 8.07 | H7: Per Ed. 2 screws + 2 nuts per bracket. Matches the 4 M5 x 8 button head 'frame 90-degree corners' in the BOM (8.04). The cross-member is one of the four 760 mm extrusions (confirmed by Ed). Wire slot: cut about 30 mm wide and about 7 mm deep into the extrusion so wires can be fed through; if you have no saw, drill holes through the centre instead. A plastic clip (a printed part from the mechanical design files, 'Cable Cap for Extrusion', row 10.32: confirmed by Ed) is fitted about 40 mm from one end. PHOTO NEEDED of the slot and the clip, for the docs. | I7: M5 x 8 button head | J7: M5 T-nut
A8: Bottom frame – centre (760 mm) extrusion: electronics mount | B8: Button head screw M5 x 8 | C8: 2 | D8: M5 spring-ball T-slot nut (KJN37001) | E8: 2 | F8: No | G8: 8.05, 8.07 | H8: Per Ed. Together with the 4 for the L brackets this makes 6, which matches the BOM's 6 x M5 x 8 button head (4 corners + 2 electronics enclosure). | I8: M5 x 8 button head | J8: M5 T-nut
A9: Electronics enclosure – standoffs | B9: Nylon standoff, M3, male-female, about 18 mm | C9: 2 | D9: – | F9: No (Ed to check whether he has any) | G9: 4.15 | H9: Per Ed: the threaded end goes through the controller board and into the housing; the cover screw goes into the other end. BOM and CAD had 20 mm: confirm the length. Ed to check whether he has any. | I9: M3 standoff, male-female (about 18 mm)
A10: Electronics enclosure – cover | B10: Countersunk screw M3 x 6, into the standoffs | C10: 2 | D10: – | F10: No | G10: 7.02 | H10: Per Ed. | I10: M3 x 6 countersunk
A11: Electronics enclosure – cover (third hole) | B11: Countersunk screw M3 x 6, into a heat-set insert in the housing | C11: 1 | D11: – | F11: No | G11: 7.02 or 7.03, 7.15 | H11: Per Ed: M3 x 6 is fine (not 8). The cover has 3 holes: 2 into the standoffs and 1 into the electronics housing. The housing holes use heat-set inserts. | I11: M3 x 6 countersunk
A12: Emerald Dingo controller board | B12: Button head screw M3 x 6 | C12: 2 | D12: – | F12: No | G12: 7.08 | H12: Per Ed: the board has 4 mounting holes. 2 are held by the standoffs (threaded through the board into the housing); the other 2 take these M3 x 6 button head screws into heat-set inserts in the housing. The housing holes in the plastic all use heat-set inserts (count to add to the M3 inserts: 3 for the screws, probably 2 more for the standoff studs). | I12: M3 x 6 button head
A13: Frame – four 50 mm legs on the bottom corner cubes | B13: Socket head (cap) screw M5 x 12 | C13: 4 | D13: None (bolts go into the tapped leg ends) | F13: No | G13: 1.04, 1.05, 8.03 | H13: Per Ed (length 12 'I think', same as the other cube bolts). 1 per leg, through the cube's third hole. Running tally of cube bolts: bottom square 8 + legs 4 = 12; the other 10 of the BOM's 22 would be the top (4 at the legs, 6 for the top rails, as the front top has no rail). To confirm when we reach the top frame. | I13: M5 x 12 cap head
A14: Metal baseboard (new bed) – on top faces of the extrusions | B14: Countersunk screw M5 x 8 | C14: 8 | D14: M5 spring-ball T-slot nut (KJN37001) | E14: 8 | F14: No | G14: 1.09, 8.01, 8.07 | H14: Per Ed: 8 mounting points = 3 on the front rail, 3 on the back rail, 2 on the left-hand side rail (top faces of the extrusions). Countersink the bed holes before the vinyl is applied. Check whether the BOM's 18 x M5 x 8 countersunk (8.01: motors, idlers, Y left/right) already includes these 8, or whether the metal bed adds 8 more. | I14: M5 x 8 countersunk | J14: M5 T-nut
A15: Y endstop mount (Y_Endstop_Mount.stl) on the front-left 50 mm leg (facing the back) | B15: Countersunk screw M5 x 8 | C15: 1 | D15: M5 spring-ball T-slot nut (KJN37001) | E15: 1 | F15: No | G15: 8.01, 8.07 | H15: Per Ed (confirmed): this is the Y endstop. The nut slides into the leg, facing the back, and the mount is fixed to it with one M5 x 8 countersunk screw. | I15: M5 x 8 countersunk | J15: M5 T-nut
A16: Y optical endstop on its mount (Y_Endstop_Mount.stl) | B16: Button head screw M3 x 6 | C16: 2 | D16: – | F16: No | G16: 7.08 | H16: Per Ed: 6 mm (6 or 8 would do). The 2 M3 screws go into the endstop mount and screw directly into threaded plastic (confirmed), so no inserts. | I16: M3 x 6 button head
A17: Power switch mount on the rear-right 50 mm leg (plastic parts to be added later) | B17: Countersunk screw M5 x 8 | C17: 2 | D17: M5 spring-ball T-slot nut (KJN37001) | E17: 2 | F17: No | G17: 8.01, 8.07 | H17: Per Ed (confirmed countersunk): one bolt + nut on the inside face of the leg facing the front of the machine, and one on the inside face facing the inside of the machine (the X direction). 2 bolts, 2 nuts. | I17: M5 x 8 countersunk | J17: M5 T-nut
A18: Energy chain mount on the right-hand 560 mm extrusion, upright (top) face, towards the back near the leg | B18: Countersunk screw M3 x 8 | C18: 1 | D18: M3 spring-ball T-slot nut (KJN43719) | E18: 1 | F18: No | G18: 7.03, 7.14 | H18: Per Ed. The BOM has 2 x M3 x 8 countersunk for 'Y right': check whether the second belongs to the same bracket (the energy chain bracket, ECB, has no STL yet). Ed on 24 Oct: the M3 x 8 connects the energy chain to an M3 sliding nut on the extrusion along the base, Y side, bottom back near the power. Confirmed by Ed: the same single screw, not a second one. | I18: M3 x 8 countersunk | J18: M3 T-nut
A19: X motor assembly (NEMA 17, toothed pulley, one toothed and one smooth idler), mounted on top of the leg section | B19: Countersunk screw M3 x 16 | C19: 2 | D19: – | F19: No | G19: 7.05 | H19: Per Ed (corrected from 8 to 16). This is the use of the M3 x 16 countersunk row added from your Allfix link. | I19: M3 x 16 countersunk
A20: X motor assembly (NEMA 17, toothed pulley, one toothed and one smooth idler), mounted on top of the leg section | B20: Countersunk screw M3 x 30 | C20: 2 | D20: – | F20: No | G20: 7.07 | H20: Per Ed (confirmed): the motor mount's M3 x 30 screws go through the plastic straight into the threaded holes in the motor. No nuts or inserts. | I20: M3 x 30 countersunk
A21: X motor assembly (NEMA 17, toothed pulley, one toothed and one smooth idler), mounted on top of the leg section | B21: Countersunk screw M5 x 8 | C21: 3 | D21: M5 spring-ball T-slot nut (KJN37001) | E21: 3 | F21: No | G21: 8.01, 8.07 | H21: Per Ed. | I21: M5 x 8 countersunk | J21: M5 T-nut
A22: X motor assembly (NEMA 17, toothed pulley, one toothed and one smooth idler), mounted on top of the leg section – corner cube | B22: Button head screw M5 x 12 | C22: 2 | D22: – | F22: No | G22: 8.04 (new M5 x 12 button head row), 8.04 | H22: Per Ed: 2 x M5 x 12 button head hold the corner cube. This is the use of the M5 x 12 button head row added from your Allfix link. The pulley's grub screws come with the pulley. Grub screws (about M3 x 4) come with the pulleys: confirmed by Ed. | I22: M5 x 12 button head
A23: Y motor assembly (same layout as the X motor) | B23: Countersunk screw M3 x 30 | C23: 2 | D23: – | F23: No | G23: 7.07 | H23: Per Ed (confirmed): screws go through the plastic into the threaded holes in the motor. No nuts or inserts. | I23: M3 x 30 countersunk
A24: Y motor assembly (same layout as the X motor) | B24: Countersunk screw M3 x 8 | C24: 2 | D24: – | F24: No | G24: 7.03 | H24: Per Ed. | I24: M3 x 8 countersunk
A25: Y motor assembly (same layout as the X motor) | B25: Countersunk screw M5 x 8 | C25: 3 | D25: M5 spring-ball T-slot nut (KJN37001) | E25: 3 | F25: No | G25: 8.01, 8.07 | H25: Confirmed by Ed: the Y motor matches the X motor (3 x M5 x 8 with 3 nuts). | I25: M5 x 8 countersunk | J25: M5 T-nut
A26: Y motor assembly (same layout as the X motor) – corner cube | B26: Button head screw M5 x 12 | C26: 2 | D26: – | F26: No | G26: 8.04 | H26: Confirmed by Ed: as the X motor. | I26: M5 x 12 button head
A27: X idler assembly (back corner; mirrored, same screws as the other side; corner cube + toothed idlers) – corner cube | B27: Button head screw M5 x 12 | C27: 3 | D27: – | F27: No | G27: 8.04 | H27: Confirmed by Ed, per side: the 3 M5 x 12 button head screws hold the corner cube and mount the plastic brackets to the extrusions. | I27: M5 x 12 button head
A28: X idler assembly (back corner; mirrored, same screws as the other side; corner cube + toothed idlers) | B28: Countersunk screw M5 x 8 | C28: 4 | D28: M5 spring-ball T-slot nut (KJN37001) | E28: 4 | F28: No | G28: 8.01, 8.07 | H28: Confirmed by Ed, per side: 4 screws with 4 nuts. | I28: M5 x 8 countersunk | J28: M5 T-nut
A29: X idler assembly (back corner; mirrored, same screws as the other side; corner cube + toothed idlers) – idler clamp, bolted from the underside | B29: Countersunk screw M5 x 20 | C29: 1 | D29: – (threaded plastic) | F29: No | G29: 8.02 | H29: Confirmed by Ed, per side: the 3 M5 x 12 button head screws hold the corner cube and mount the plastic brackets to the extrusions. Confirmed by Ed: 1 per side (not 2). Of the two idlers, one has its axle printed in place and the other uses this bolt as its axle. Total with the gantry's 4 = 6 M5 x 20 (Ed). Confirmed by Ed: it screws into a threaded plastic piece, so no nut. | I29: M5 x 20 countersunk
A30: Y idler assembly (back corner; mirrored, same screws as the other side; corner cube + toothed idlers) – corner cube | B30: Button head screw M5 x 12 | C30: 3 | D30: – | F30: No | G30: 8.04 | H30: Confirmed by Ed, per side: the 3 M5 x 12 button head screws hold the corner cube and mount the plastic brackets to the extrusions. | I30: M5 x 12 button head
A31: Y idler assembly (back corner; mirrored, same screws as the other side; corner cube + toothed idlers) | B31: Countersunk screw M5 x 8 | C31: 4 | D31: M5 spring-ball T-slot nut (KJN37001) | E31: 4 | F31: No | G31: 8.01, 8.07 | H31: Confirmed by Ed, per side: 4 screws with 4 nuts. | I31: M5 x 8 countersunk | J31: M5 T-nut
A32: Y idler assembly (back corner; mirrored, same screws as the other side; corner cube + toothed idlers) – idler clamp, bolted from the top side | B32: Countersunk screw M5 x 20 | C32: 1 | D32: – (threaded plastic) | F32: No | G32: 8.02 | H32: Confirmed by Ed, per side: the 3 M5 x 12 button head screws hold the corner cube and mount the plastic brackets to the extrusions. Confirmed by Ed: 1 per side (not 2). Of the two idlers, one has its axle printed in place and the other uses this bolt as its axle. Total with the gantry's 4 = 6 M5 x 20 (Ed). Confirmed by Ed: it screws into a threaded plastic piece, so no nut. | I32: M5 x 20 countersunk
A33: Y linear rail MGN9H (black) under the left-hand top extrusion | B33: Socket head (cap) screw M3 x 8 | C33: 4 | D33: M3 spring-ball T-slot nut (KJN43719) | E33: 4 | F33: No | G33: 7.12, 7.14 | H33: Per Ed: only about 4 fixings per rail are needed, although the rail has more holes. 4 per side, 8 in total. | I33: M3 x 8 socket head | J33: M3 T-nut
A34: Y linear rail MGN9H (black) under the right-hand top extrusion | B34: Socket head (cap) screw M3 x 8 | C34: 4 | D34: M3 spring-ball T-slot nut (KJN43719) | E34: 4 | F34: No | G34: 7.12, 7.14 | H34: Per Ed: only about 4 fixings per rail are needed, although the rail has more holes. 4 per side, 8 in total. | I34: M3 x 8 socket head | J34: M3 T-nut
A35: Gantry end, X side (Y homing arm side): MGN9H block, plate, idler block | B35: Countersunk screw M3 x 6 | C35: 2 | D35: – | F35: No | G35: 7.02 | H35: Per Ed: into the MGN9H block, fixing the plate. | I35: M3 x 6 countersunk
A36: Gantry end, X side (Y homing arm side): MGN9H block, plate, idler block – Y homing (endstop) arm bracket | B36: Countersunk screw M3 x 8 | C36: 2 | D36: – | F36: No | G36: 7.03 | H36: Confirmed by Ed: 2 on the X side (the Y homing arm); none on the Y side. | I36: M3 x 8 countersunk
A37: Gantry end, X side (Y homing arm side): MGN9H block, plate, idler block – idler block to the 710 mm X rail | B37: Countersunk screw M5 x 20 | C37: 2 | D37: M5 spring-ball T-slot nut (KJN37001) | E37: 2 | F37: No | G37: 8.02, 8.07 | H37: Confirmed by Ed: 2 per side, separate from the idler axle/clamp bolt (1 per side). M5 x 20 total: 2 idler + 4 gantry = 6. | I37: M5 x 20 countersunk | J37: M5 T-nut
A38: Gantry end, X side (Y homing arm side): MGN9H block, plate, idler block – top plate | B38: Countersunk screw M5 x 8 | C38: 2 | D38: M5 spring-ball T-slot nut (KJN37001) | E38: 2 | F38: No | G38: 8.01, 8.07 | H38: Confirmed by Ed: countersunk. 2 per side into M5 sliding nuts on the top plate. | I38: M5 x 8 countersunk | J38: M5 T-nut
A39: Gantry end, X side (Y homing arm side): MGN9H block, plate, idler block – clamp top to bottom | B39: Countersunk screw M3 x 8 | C39: 1 | D39: – | F39: No | G39: 7.03 | H39: Confirmed by Ed: 1 per side. With the homing arm's 2, the X side has 3 of these screws and the Y side has 1. Idlers: a smooth one at the front and a toothed one (rounded D-shape) facing the back. | I39: M3 x 8 countersunk
A40: Gantry end, Y side (no homing arm): MGN9H block, plate, idler block | B40: Countersunk screw M3 x 6 | C40: 4 | D40: – | F40: No | G40: 7.02 | H40: Per Ed: the Y side has 4 M3 x 6 countersunk on the block (no homing bracket). | I40: M3 x 6 countersunk
A41: Gantry end, Y side (no homing arm): MGN9H block, plate, idler block – idler block to the X rail | B41: Countersunk screw M5 x 20 | C41: 2 | D41: M5 spring-ball T-slot nut (KJN37001) | E41: 2 | F41: No | G41: 8.02, 8.07 | H41: Confirmed by Ed: 2 per side, separate from the idler axle/clamp bolt (1 per side). M5 x 20 total: 2 idler + 4 gantry = 6. | I41: M5 x 20 countersunk | J41: M5 T-nut
...

Sheet Fixings totals
A1: Fixings totals – from the walk-through (the 'real' figures, work in progress)
A2: Counted from 'Fixings by part' as the build is walked through bottom frame upwards. The old BOM fixing quantities are shown only for comparison and are replaced once the walk-through is finished.
A4: Fixing | B4: Walk-through total so far | C4: Old BOM qty (for comparison) | D4: Notes
A5: M3 x 16 button head (approx.) | B5: =SUMIF('Fixings by part'!$I:$I,A5,'Fixings by part'!$C:$C) -> 4 | C5: 4 | D5: Old BOM: M3 x 12 button head for the feet (7.10). Feet come with their screws.
A6: M3 x 6 countersunk | B6: =SUMIF('Fixings by part'!$I:$I,A6,'Fixings by part'!$C:$C) -> 17 | C6: 21 | D6: Electronics cover (3) so far, plus the gantry blocks.
A7: M3 x 6 button head | B7: =SUMIF('Fixings by part'!$I:$I,A7,'Fixings by part'!$C:$C) -> 6 | C7: 4 | D7: Controller board.
A8: M3 standoff, male-female (about 18 mm) | B8: =SUMIF('Fixings by part'!$I:$I,A8,'Fixings by part'!$C:$C) -> 2 | C8: 2 | D8: Old BOM: nylon standoff M3 x 20.
A9: M3 T-nut | B9: =SUMIF('Fixings by part'!$J:$J,A9,'Fixings by part'!$E:$E) -> 17 | C9: 16 | D9: Feet so far. You think about 13 in total.
A10: M5 x 12 cap head | B10: =SUMIF('Fixings by part'!$I:$I,A10,'Fixings by part'!$C:$C) -> 12 | C10: 22 | D10: Bottom square 8 + legs 4 so far; top frame still to do.
A11: M5 x 8 button head | B11: =SUMIF('Fixings by part'!$I:$I,A11,'Fixings by part'!$C:$C) -> 6 | C11: 6 | D11: L brackets 4 + electronics mount 2.
A12: M5 x 8 countersunk | B12: =SUMIF('Fixings by part'!$I:$I,A12,'Fixings by part'!$C:$C) -> 33 | C12: 18 | D12: Includes the 4 chain support screws.
A13: M5 T-nut | B13: =SUMIF('Fixings by part'!$J:$J,A13,'Fixings by part'!$E:$E) -> 43 | C13: 50 | D13: Placeholder 50 in the BOM.
A14: M3 x 8 countersunk | B14: =SUMIF('Fixings by part'!$I:$I,A14,'Fixings by part'!$C:$C) -> 15 | C14: 2 | D14: Energy chain mount so far.
A15: M3 x 30 countersunk | B15: =SUMIF('Fixings by part'!$I:$I,A15,'Fixings by part'!$C:$C) -> 4 | C15: 4 | D15: X motor so far (2 of 4).
A16: M5 x 12 button head | B16: =SUMIF('Fixings by part'!$I:$I,A16,'Fixings by part'!$C:$C) -> 10 | D16: Corner cube at the X motor so far.
A17: M3 x 16 countersunk | B17: =SUMIF('Fixings by part'!$I:$I,A17,'Fixings by part'!$C:$C) -> 5 | D17: X motor so far.
A18: M5 x 20 countersunk | B18: =SUMIF('Fixings by part'!$I:$I,A18,'Fixings by part'!$C:$C) -> 6 | C18: 4 | D18: Idler bolts 2 + gantry 4 = 6 (Ed); the old BOM had 4.
A19: M3 x 8 socket head | B19: =SUMIF('Fixings by part'!$I:$I,A19,'Fixings by part'!$C:$C) -> 14 | C19: 12 | D19: Y rails so far (8); the old 12 'frame – rails' probably includes 4 for the X rail.
A20: Cable tie, black | B20: =SUMIF('Fixings by part'!$I:$I,A20,'Fixings by part'!$C:$C) -> 1 | D20: Y-side wiring only so far.
A21: M3 heat-set insert | B21: =SUMIF('Fixings by part'!$I:$I,A21,'Fixings by part'!$C:$C) -> 1 | C21: 26 | D21: Electronics tray so far (5). The old BOM had 26 for all printed parts, a pack of 50 at £5.90.
A22: M3 x 5 countersunk | B22: =SUMIF('Fixings by part'!$I:$I,A22,'Fixings by part'!$C:$C) -> 6 | C22: 11 | D22: Y gantry underside (energy chain) so far.
A23: M2 x 8 socket head | B23: =SUMIF('Fixings by part'!$I:$I,A23,'Fixings by part'!$C:$C) -> 7 | D23: MGN7H rail 3 + pen holder 4 so far.
A24: M2 heat-set insert | B24: =SUMIF('Fixings by part'!$J:$J,A24,'Fixings by part'!$E:$E) -> 3 | C24: 4 | D24: Plate inserts so far.
A25: M3 nyloc nut | B25: 2 | C25: 2 | D25: Z tool head: spring so far (1).
A26: M3 x 8 button head (Z add-on only) | B26: =SUMIF('Fixings by part'!$I:$I,A26,'Fixings by part'!$C:$C) -> 1 | D26: Z add-on builds only.

Sheet Cable leads
A1: Cable leads
A2: Cut and strip details for each lead. Also the source for the build documentation.
A4: Lead | B4: Cores | C4: AWG | D4: Sheath | E4: Length (mm) | F4: Strip at motor end (mm) | G4: Strip at controller end (mm) | H4: Connectors | I4: Notes
A5: Y motor | B5: 4 | C5: 24 | D5: PVC, flexible, unshielded | E5: 515 | F5: 27-30 | G5: 17-20 | H5: Controller end: JST PH 2.0 4-way. Motor end: JST PH 2.0 6-way, cores in positions 1, 3, 4 and 6 (2 and 5 empty). | I5: Shielded cable is tricky for this lead because it needs to flex. Core colours on your cable: yellow, blue, green, red (varies by supplier). Colour-to-pin mapping still to document.
A6: X motor | B6: 4 | C6: 24 | D6: PVC, flexible, unshielded | E6: 920 | F6: 27-30 | G6: 17-20 | H6: Controller end: JST PH 2.0 4-way. Motor end: JST PH 2.0 6-way, cores in positions 1, 3, 4 and 6 (2 and 5 empty). | I6: Same as the Y lead except for length. Core colours on your cable: yellow, blue, green, red (varies by supplier). Colour-to-pin mapping still to document.
A7: X endstop | B7: 3 x single core | C7: 26 | D7: None: 3 loose single cores (Alpha Wire 3049 BK001), colour-taped at both ends | E7: 2100 | F7: to confirm | G7: to confirm | H7: Female JST SM on the wire (pitch to confirm; JST SM is normally 2.5 mm) plugs into the male on the endstop module. Controller end: JST PH 2.0 3-way (assumed). | I7: POLARITY: match the lead's wire order to the board header and the module pins (module is SIG / GND / VCC). Runs through the 7 x 7 energy chain, hence single cores. Same length as the Z lead. Pin order on both ends still to document.
A8: Y endstop | B8: 3 | C8: 26 (confirm) | D8: PVC | E8: 920 | F8: to confirm | G8: to confirm | H8: Female JST SM on the wire (pitch to confirm; JST SM is normally 2.5 mm) plugs into the male on the endstop module. Controller end: JST PH 2.0 3-way (assumed). | I8: POLARITY: match the lead's wire order to the board header and the module pins (module is SIG / GND / VCC). Same length as the X motor lead (920 mm), where it is housed next to the motor. Sheathed 3-core assumed since it doesn't go through the energy chain; confirm.
A9: Z motor | B9: 4 x single core | C9: 26 | D9: None: 4 loose single cores (Alpha Wire 3049 BK001, black PVC, tinned copper), colour-taped at both ends | E9: 2100 | F9: – | G9: – | H9: Motor end: female JST SM, mating with a male JST SM fitted to the NEMA 14's lead (cut to 30-40 mm from the motor). Controller end: white JST PH 2.0 4-way, pins 1 to 4 all used. | I9: Runs through the 7 x 7 energy chain, hence single cores. Tape a thin strip of a different colour on both ends of each wire (e.g. red on both ends of one, green on both ends of another). 2100 mm leaves a little slack.
